Workbook

Sheet 21 Oct Mon
A1: =CONCATENATE("DAILY REPORT DATE: ",MID(CELL("filename",A1),FIND("]",CELL("filename",A1),1)+1,255)) -> #VALUE! | AU1: =A1 -> #VALUE!
A3: COLLEGE NAME : L.J. INSTITUTE OF ENGINEERING AND TECHNOLOGY DEPARTMENT NAME : SY4(CST CS&IT) YEAR : 2024-25 SEMESTER : III | AU3: =A3 -> COLLEGE NAME : L.J. INSTITUTE OF ENGINEERING AND TECHNOLOGY DEPARTMENT NAME : SY4(CST CS&IT) YEAR : 2024-25 SEMESTER : III
A4: TEACHING SECTION | AU4: NON TEACHING SECTION | CH4: HOD SECTION
A5: LECTURE DETAILS | AA5: Difficulty solving or if attendance is less than 5 /Whatsapp Doubt Solving in official group / Students details whose Home Visit was done / PTM (Roll No,Name, Contact No.) (H) | AJ5: Project / Dissertation/Design Engineering Load (Enter only if Answer is given by Guide of the technical query) | AP5: Total Teaching Credits (A) | AQ5: Teaching Feedback (B) | AR5: Effective Teaching Credit C= A * B | AS5: NT Total Credits (D) Refer from NT Section | AT5: Final Teaching + Non Teaching Credit E =C*0.75+D*0.25 | AU5: Once in a Semester | AY5: Load Adjustment Done | AZ5: AttendanceSubmission.If Not submitted | BA5: Examination | BP5: PARENTS INTERACTION | BV5: SIF Credit | BX5: Extra Activity
A6: Sr No | B6: Name-DOJ-Mobile No. | C6: Lec. No | D6: Faculty Initials | E6: Lecture Details | M6: No. of Students Present | N6: Total Students | O6: Effective Load | P6: Today's Eff.Load Alloted as per TT | Q6: Extra Load | R6: Merged Load (If student in proxy batch < 20, mention (-1) for 2 hrs Lab or (-1.5) for 2 hrs TL | S6: Overall Today's Effective Load | T6: Today's Eff. Mass bunk | U6: Today's Eff.load cancel bcz of Holiday | V6: Today's Eff load cancel bcz of Specific reason | W6: Today's Eff load cancel bcz no adjustment was possible | X6: Today's Total Eff Load Expected from Faculty | Y6: Today's Eff.Load Taken | Z6: Comment for dummy column name C,D,E (Holiday, or load cacnelled details) | AU6: Submission of Subject Folder (LP, QB,MSE Syllabus, Ques Paper etc) Enter Credit=0 if done on time, Else (-1) daily until submitted | AV6: Timetable Preparation Credit as per GI | AW6: No.of Project/Dissertation Groups handled (To be entered at the end of semester) | AX6: No.of Marks Entry in GTU Portal | BA6: Supervision during College Exam | BJ6: Paper Setting | BK6: Paper Solution | BL6: Paper Evaluation | BO6: Paper Showing | BP6: Home Visit Credit & Enter details in (H-Teaching Section) (Credit =1 - Meeting with Mother Credit = 1.5 - Meeting with Father) | BQ6: No. of Phone Calls and entered in SIF | BT6: No. of SMS done | BU6: Personal Discussion with parents in Institute (0.25 credit per student) | BV6: Enter Credit for Personal Information in Page 1 and Page 2 | BW6: Enter credit for any entry work done in SIF | BX6: Extra Activity in hours as per General Instructions. | CF6: Not Defined as per General Instruction (Enter in terms of Hrs) | CH6: Leave Status | CJ6: Error in Work done | CL6: Delay in Work Done | CN6: Any other HOD Comment | CP6: Description of Work refused by faculty or done after doing arguments with HOD | CQ6: Enter credit if Faculty Refusd to do work given by HOD. Credit = (-5) | CR6: Enter credit if Faculty does work after doing arguments with HOD. Credit = (-2) | CS6: HOD Positive Credit and Faculty Negative Credit | CT6: Total NT Credits
E7: Course (UG/PG) | F7: Dept | G7: SEM (Only Roman Number) | H7: Div | I7: Batch | J7: Sub. | K7: Lec/ Lab/Tut/ELec/ELab/ETut/PLec/Plab/PTut/SLec/SLab/Stut/TL/ETL/STL/PTL | L7: Faculty Initials for Proxy Lecture Only a) Faculty who was given the proxy b) Faculty whose proxy was taken | O7: G | P7: A1 | Q7: A2 | R7: A3 | S7: A=A1+A2+A3 | T7: B | U7: C | V7: D | W7: E | X7: F= A-B-C-D-E | Y7: G(G-F) | AA7: Enter Purpose Short Form DS - Difficulty Solving HV - Home Visit WA - Whatsapp AL5 - Attendance Less than 5 PTM - Parents Teacher Meeting at Institute | AB7: Sem | AC7: Div | AD7: Roll No | AE7: Name | AF7: Mobile | AG7: No.of Students Present | AH7: Time (Only for difficulty solving) | AI7: Total No.of Hours (Only for difficulty solving) | AJ7: Group Code (Format : UG/PG_Branch_SEMNo_GroupNo Ex : UG_ME_SEM4_8) | AK7: Technical Question asked by student | AL7: Date & Time (Start time : End Time) | AM7: Duration in hours | AN7: Name of the Student who asked the question | AO7: Mobile No of the student | AY7: (Credit 0.1 for 1 effective hour of load adjustment done) | AZ7: Enter (-1) upto each day of delay else 0 if submitted on time | BA7: Today's No of Assign Supervision | BB7: Session (Morning / Afternoon) | BC7: Block No | BD7: Room No | BE7: Assigned /Proxy / Swap | BF7: Faculty Short Name whose Proxy is taken / with whom Swapping is done | BG7: Today's taken Supervision (MSE) | BH7: Today's taken Supervision (REM) | BI7: Today's No of blocks handle by MSE exam coordinator | BJ7: Credit (MSE I,II =0.5*no of papers, REM =0.25*no of papers) | BK7: Credit 1 for preparing 50% solution with detailing) Enter credit | BL7: Enter Credit of MSE Paper Evaluated Section A and B both (1 credit =15 papers) | BM7: Enter Credit of MSE Paper Evaluated-Any one Section A or B (1 credit =30 papers) | BN7: Enter Credit of Rem Paper Evaluated (1 credit =30 papers) | BO7: No. of Class | BQ7: Phone Call Description | BR7: Received Phone Call | BS7: Not Received Phone Call | BX7: Sports | BY7: Cultural | BZ7: GTU Related Work Only for GTU Coordinators | CA7: COE | CB7: Techventure | CC7: Any Technical Events | CD7: Any Other Activity Description | CE7: Total Credit | CF7: Activity Description | CG7: Total hr | CH7: Leave Taken | CI7: Leave Credit (Enter Negative Value) | CJ7: Description of Error done | CK7: Error Credit (Enter only Negative Value of Credit) | CL7: Description of Delay done | CM7: No. of Days of late submission (Enter only Negative Value of Credit) | CN7: Description | CO7: Credit ( Enter Negative value if comment for negative credit)
A8: 1 | B8: Ms. Sneha Shah DOJ: 9/7/2012 MOB: 9067822170 | C8: 1 | D8: STS | O8: =IF(AND(M8<>0,M8<>"m",M8<>"",RIGHT(K8,3)="Lec"),1,IF(AND(M8<>0,M8<>"m",M8<>"",OR(RIGHT(K8,3)="Lab",RIGHT(K8,3)="Tut")),0.5,IF(AND(M8<>0,M8<>"m",M8<>"",RIGHT(K8,2)="TL"),0.75,0))) -> 0 | P8: =COUNTIF(K8:K18,"TL")*0.75+COUNTIF(K8:K18,"Lec")*1+COUNTIF(K8:K18,"Lab")*0.5 -> 0 | Q8: =SUM((IF(LEFT(K8,1)="E",O8,0)),(IF(LEFT(K9,1)="E",O9,0)),(IF(LEFT(K10,1)="E",O10,0)),(IF(LEFT(K11,1)="E",O11,0)),(IF(LEFT(K12,1)="E",O12,0)),(IF(LEFT(K13,1)="E",O13,0)),(IF(LEFT(K14,1)="E",O14,0)),(IF(LEFT(K15,1)="E",O15,0)),(IF(LEFT(K16,1)="E",O16,0)),(IF(LEFT(K17,1)="E",O17,0)),(IF(LEFT(K18,1)="E",O18,0))) -> 0 | R8: =SUM(IF(M14<20,IF(K14="Plec",-1,IF(K14="PTL",-0.75,IF(K14="Plab",-0.5,0))),0),IF(M15<20,IF(K15="Plec",-1,IF(K15="PTL",-0.75,IF(K15="Plab",-0.5,0))),0),IF(M16<20,IF(K16="Plec",-1,IF(K16="PTL",-0.75,IF(K16="Plab",-0.5,0))),0),IF(M17<20,IF(K17="Plec",-1,IF(K17="PTL",-0.75,IF(K17="Plab",-0.5,0))),0)) -> 0 | S8: =SUM(P8:R18) -> 0 | T8: =SUM(IF(M8="M",IF(OR(K8="lec",K8="plec",K8="slec"),1,IF(OR(K8="lab",K8="plab",K8="slab",K8="tut",K8="ptut",K8="stut"),0.5,IF(OR(K8="TL",K8="pTL",K8="STL"),0.75,0))),0),IF(M9="M",IF(OR(K9="lec",K9="plec",K9="slec"),1,IF(OR(K9="lab",K9="plab",K9="slab",K9="tut",K9="ptut",K9="stut"),0.5,IF(OR(K9="TL",K9="pTL",K9="STL"),0.75,0))),0),IF(M10="M",IF(OR(K10="lec",K10="plec",K10="slec"),1,IF(OR(K10="lab",K10="plab",K10="slab",K10="tut",K10="ptut",K10="stut"),0.5,IF(OR(K10="TL",K10="pTL",K10="STL"),0.75,0))),0),IF(M11="M",IF(OR(K11="lec",K11="plec",K11="slec"),1,IF(OR(K11="lab",K11="plab",K11="slab",K11="tut",K11="ptut",K11="stut"),0.5,IF(OR(K11="TL",K11="pTL",K11="STL"),0.75,0))),0),IF(M12="M",IF(OR(K12="lec",K12="plec",K12="slec"),1,IF(OR(K12="lab",K12="plab",K12="slab",K12="tut",K12="ptut",K12="stut"),0.5,IF(OR(K12="TL",K12="pTL",K12="STL"),0.75,0))),0),IF(M13="M",IF(OR(K13="lec",K13="plec",K13="slec"),1,IF(OR(K13="lab",K13="plab",K13="slab",K13="tut",K13="ptut",K13="stut"),0.5,IF(OR(K13="TL",K13="pTL",K13="STL"),0.75,0))),0),IF(M14="M",IF(OR(K14="lec",K14="plec",K14="slec"),1,IF(OR(K14="lab",K14="plab",K14="slab",K14="tut",K14="ptut",K14="stut"),0.5,IF(OR(K14="TL",K14="pTL",K14="STL"),0.75,0))),0),IF(M15="M",IF(OR(K15="lec",K15="plec",K15="slec"),1,IF(OR(K15="lab",K15="plab",K15="slab",K15="tut",K15="ptut",K15="stut"),0.5,IF(OR(K15="TL",K15="pTL",K15="STL"),0.75,0))),0),IF(M16="M",IF(OR(K16="lec",K16="plec",K16="slec"),1,IF(OR(K16="lab",K16="plab",K16="slab",K16="tut",K16="ptut",K16="stut"),0.5,IF(OR(K16="TL",K16="pTL",K16="STL"),0.75,0))),0),IF(M17="M",IF(OR(K17="lec",K17="plec",K17="slec"),1,IF(OR(K17="lab",K17="plab",K17="slab",K17="tut",K17="ptut",K17="stut"),0.5,IF(OR(K17="TL",K17="pTL",K17="STL"),0.75,0))),0),IF(M18="M",IF(OR(K18="lec",K18="plec",K18="slec"),1,IF(OR(K18="lab",K18="plab",K18="slab",K18="tut",K18="ptut",K18="stut"),0.5,IF(OR(K18="TL",K18="pTL",K18="STL"),0.75,0))),0)) -> 0 | X8: =S8-(T8+U8+V8+W8) -> 0 | Y8: =CONCATENATE(SUM(O8:O18),"(",SUM(O8:O18)-X8,")") -> 0(0) | AA8: PTM | AB8: III | AC8: D6 | AD8: 193 | AE8: PRAJAPATI DIVYESHKUMAR PRAKASHBHAI | AF8: 7016117524 | AG8: 1 | AP8: =SUM(SUM(O8:O18),SUM(AI8:AI18)/2,AM8) -> 0 | AR8: =AP8*AQ8 -> 0 | AS8: =CT8 -> 1 | AT8: =AR8*0.75+AS8*0.25 -> 0.25 | BU8: 1 | CF8: 3 PTM Done on Saturday (19th Oct ) | CS8: =SUM(CS19:CS305) -> 3 | CT8: =SUM(AU8,AV8,AW8,AX8/400,AY8,AZ8,BG8,BH8*0.5,BI8*0.25,BJ8,BK8,BL8,BM8,BN8,BO8,BP8,BR8/20,BS8/100,BT8/60,BU8,BV8,BW8,BX8/4,SUM(BY8:CC18)/3,CE8,CG8/3,CI8,CK8,CM8,CO8,CQ8,CR8) -> 1 | CU8: =D8 -> STS
C9: 2 | D9: STS | O9: =IF(AND(M9<>0,M9<>"m",M9<>"",RIGHT(K9,3)="Lec"),1,IF(AND(M9<>0,M9<>"m",M9<>"",OR(RIGHT(K9,3)="Lab",RIGHT(K9,3)="Tut")),0.5,IF(AND(M9<>0,M9<>"m",M9<>"",RIGHT(K9,2)="TL"),0.75,0))) -> 0 | AA9: PTM | AB9: III | AC9: D6 | AD9: 203 | AE9: PATEL SHREY VIJAYBHAI | AF9: 7862806197 | AG9: 1 | CU9: =D9 -> STS
C10: 3 | D10: STS | O10: =IF(AND(M10<>0,M10<>"m",M10<>"",RIGHT(K10,3)="Lec"),1,IF(AND(M10<>0,M10<>"m",M10<>"",OR(RIGHT(K10,3)="Lab",RIGHT(K10,3)="Tut")),0.5,IF(AND(M10<>0,M10<>"m",M10<>"",RIGHT(K10,2)="TL"),0.75,0))) -> 0 | AA10: PTM | AB10: III | AC10: D6 | AD10: 190 | AE10: PATEL MEET JITENDRABHAI | AF10: 6351338386 | AG10: 1 | CU10: =D10 -> STS
C11: 4 | D11: STS | O11: =IF(AND(M11<>0,M11<>"m",M11<>"",RIGHT(K11,3)="Lec"),1,IF(AND(M11<>0,M11<>"m",M11<>"",OR(RIGHT(K11,3)="Lab",RIGHT(K11,3)="Tut")),0.5,IF(AND(M11<>0,M11<>"m",M11<>"",RIGHT(K11,2)="TL"),0.75,0))) -> 0 | AA11: PTM | AB11: III | AC11: D6 | AD11: 208 | AE11: DHOLARIYA JEPIL NITINBHAI | AF11: 6351655644 | AG11: 1 | CU11: =D11 -> STS
C12: 5 | D12: STS | O12: =IF(AND(M12<>0,M12<>"m",M12<>"",RIGHT(K12,3)="Lec"),1,IF(AND(M12<>0,M12<>"m",M12<>"",OR(RIGHT(K12,3)="Lab",RIGHT(K12,3)="Tut")),0.5,IF(AND(M12<>0,M12<>"m",M12<>"",RIGHT(K12,2)="TL"),0.75,0))) -> 0 | CU12: =D12 -> STS
C13: 6 | D13: STS | O13: =IF(AND(M13<>0,M13<>"m",M13<>"",RIGHT(K13,3)="Lec"),1,IF(AND(M13<>0,M13<>"m",M13<>"",OR(RIGHT(K13,3)="Lab",RIGHT(K13,3)="Tut")),0.5,IF(AND(M13<>0,M13<>"m",M13<>"",RIGHT(K13,2)="TL"),0.75,0))) -> 0 | CU13: =D13 -> STS
C14: 7 | D14: STS | O14: =IF(AND(M14>=20,M14<>"m",RIGHT(K14,3)="Lec"),1,IF(AND(M14>=20,M14<>"m",OR(RIGHT(K14,3)="Lab",RIGHT(K14,3)="Tut")),0.5,IF(AND(M14>=20,M14<>"m",RIGHT(K14,2)="TL"),0.75,0))) -> 0 | CU14: =D14 -> STS
C15: 8 | D15: STS | O15: =IF(AND(M15>=20,M15<>"m",RIGHT(K15,3)="Lec"),1,IF(AND(M15>=20,M15<>"m",OR(RIGHT(K15,3)="Lab",RIGHT(K15,3)="Tut")),0.5,IF(AND(M15>=20,M15<>"m",RIGHT(K15,2)="TL"),0.75,0))) -> 0 | CU15: =D15 -> STS
C16: 9 | D16: STS | O16: =IF(AND(M16>=20,M16<>"m",RIGHT(K16,3)="Lec"),1,IF(AND(M16>=20,M16<>"m",OR(RIGHT(K16,3)="Lab",RIGHT(K16,3)="Tut")),0.5,IF(AND(M16>=20,M16<>"m",RIGHT(K16,2)="TL"),0.75,0))) -> 0 | CU16: =D16 -> STS
C17: 10 | D17: STS | O17: =IF(AND(M17>=20,M17<>"m",RIGHT(K17,3)="Lec"),1,IF(AND(M17>=20,M17<>"m",OR(RIGHT(K17,3)="Lab",RIGHT(K17,3)="Tut")),0.5,IF(AND(M17>=20,M17<>"m",RIGHT(K17,2)="TL"),0.75,0))) -> 0 | CU17: =D17 -> STS
C18: 11 | D18: STS | O18: =IF(AND(M18<>0,M18<>"m",M18<>"",RIGHT(K18,3)="Lec"),1,IF(AND(M18<>0,M18<>"m",M18<>"",OR(RIGHT(K18,3)="Lab",RIGHT(K18,3)="Tut")),0.5,IF(AND(M18<>0,M18<>"m",M18<>"",RIGHT(K18,2)="TL"),0.75,0))) -> 0 | CU18: =D18 -> STS
A19: 2 | B19: Mr.Darshan Bhatt DOJ: 20/07/2022 MOB: 7227888101 | C19: 1 | D19: DVB | O19: =IF(AND(M19<>0,M19<>"m",M19<>"",RIGHT(K19,3)="Lec"),1,IF(AND(M19<>0,M19<>"m",M19<>"",OR(RIGHT(K19,3)="Lab",RIGHT(K19,3)="Tut")),0.5,IF(AND(M19<>0,M19<>"m",M19<>"",RIGHT(K19,2)="TL"),0.75,0))) -> 0 | P19: =COUNTIF(K19:K29,"TL")*0.75+COUNTIF(K19:K29,"Lec")*1+COUNTIF(K19:K29,"Lab")*0.5 -> 0 | Q19: =SUM((IF(LEFT(K19,1)="E",O19,0)),(IF(LEFT(K20,1)="E",O20,0)),(IF(LEFT(K21,1)="E",O21,0)),(IF(LEFT(K22,1)="E",O22,0)),(IF(LEFT(K23,1)="E",O23,0)),(IF(LEFT(K24,1)="E",O24,0)),(IF(LEFT(K25,1)="E",O25,0)),(IF(LEFT(K26,1)="E",O26,0)),(IF(LEFT(K27,1)="E",O27,0)),(IF(LEFT(K28,1)="E",O28,0)),(IF(LEFT(K29,1)="E",O29,0))) -> 0 | R19: =SUM(IF(M25<20,IF(K25="Plec",-1,IF(K25="PTL",-0.75,IF(K25="Plab",-0.5,0))),0),IF(M26<20,IF(K26="Plec",-1,IF(K26="PTL",-0.75,IF(K26="Plab",-0.5,0))),0),IF(M27<20,IF(K27="Plec",-1,IF(K27="PTL",-0.75,IF(K27="Plab",-0.5,0))),0),IF(M28<20,IF(K28="Plec",-1,IF(K28="PTL",-0.75,IF(K28="Plab",-0.5,0))),0)) -> 0 | S19: =SUM(P19:R29) -> 0 | T19: =SUM(IF(M19="M",IF(OR(K19="lec",K19="plec",K19="slec"),1,IF(OR(K19="lab",K19="plab",K19="slab",K19="tut",K19="ptut",K19="stut"),0.5,IF(OR(K19="TL",K19="pTL",K19="STL"),0.75,0))),0),IF(M20="M",IF(OR(K20="lec",K20="plec",K20="slec"),1,IF(OR(K20="lab",K20="plab",K20="slab",K20="tut",K20="ptut",K20="stut"),0.5,IF(OR(K20="TL",K20="pTL",K20="STL"),0.75,0))),0),IF(M21="M",IF(OR(K21="lec",K21="plec",K21="slec"),1,IF(OR(K21="lab",K21="plab",K21="slab",K21="tut",K21="ptut",K21="stut"),0.5,IF(OR(K21="TL",K21="pTL",K21="STL"),0.75,0))),0),IF(M22="M",IF(OR(K22="lec",K22="plec",K22="slec"),1,IF(OR(K22="lab",K22="plab",K22="slab",K22="tut",K22="ptut",K22="stut"),0.5,IF(OR(K22="TL",K22="pTL",K22="STL"),0.75,0))),0),IF(M23="M",IF(OR(K23="lec",K23="plec",K23="slec"),1,IF(OR(K23="lab",K23="plab",K23="slab",K23="tut",K23="ptut",K23="stut"),0.5,IF(OR(K23="TL",K23="pTL",K23="STL"),0.75,0))),0),IF(M24="M",IF(OR(K24="lec",K24="plec",K24="slec"),1,IF(OR(K24="lab",K24="plab",K24="slab",K24="tut",K24="ptut",K24="stut"),0.5,IF(OR(K24="TL",K24="pTL",K24="STL"),0.75,0))),0),IF(M25="M",IF(OR(K25="lec",K25="plec",K25="slec"),1,IF(OR(K25="lab",K25="plab",K25="slab",K25="tut",K25="ptut",K25="stut"),0.5,IF(OR(K25="TL",K25="pTL",K25="STL"),0.75,0))),0),IF(M26="M",IF(OR(K26="lec",K26="plec",K26="slec"),1,IF(OR(K26="lab",K26="plab",K26="slab",K26="tut",K26="ptut",K26="stut"),0.5,IF(OR(K26="TL",K26="pTL",K26="STL"),0.75,0))),0),IF(M27="M",IF(OR(K27="lec",K27="plec",K27="slec"),1,IF(OR(K27="lab",K27="plab",K27="slab",K27="tut",K27="ptut",K27="stut"),0.5,IF(OR(K27="TL",K27="pTL",K27="STL"),0.75,0))),0),IF(M28="M",IF(OR(K28="lec",K28="plec",K28="slec"),1,IF(OR(K28="lab",K28="plab",K28="slab",K28="tut",K28="ptut",K28="stut"),0.5,IF(OR(K28="TL",K28="pTL",K28="STL"),0.75,0))),0),IF(M29="M",IF(OR(K29="lec",K29="plec",K29="slec"),1,IF(OR(K29="lab",K29="plab",K29="slab",K29="tut",K29="ptut",K29="stut"),0.5,IF(OR(K29="TL",K29="pTL",K29="STL"),0.75,0))),0)) -> 0 | X19: =S19-(T19+U19+V19+W19) -> 0 | Y19: =CONCATENATE(SUM(O19:O29),"(",SUM(O19:O29)-X19,")") -> 0(0) | AP19: =SUM(SUM(O19:O29),SUM(AI19:AI29)/2,AM19) -> 0 | AR19: =AP19*AQ19 -> 0 | AS19: =CT19 -> 5.2 | AT19: =AR19*0.75+AS19*0.25 -> 1.3 | BA19: 1 | BB19: Morning | BC19: 3 | BD19: 108-2 | BE19: Assigned | BG19: 1 | BJ19: 4 | BQ19: Week-3 less attendance phone call to parent | BR19: 4 | BS19: 0 | CF19: Paper setting of SEM-III DE-T1 Exam | CS19: =SUM(IF(AU19<0,ABS(AU19),0),IF(AZ19<0,ABS(AZ19),0),ABS(CI19),ABS(CK19),ABS(CM19),ABS(CO19),ABS(CQ19),ABS(CR19)) -> 0 | CT19: =SUM(AU19,AV19,AW19,AX19/400,AY19,AZ19,BG19,BH19*0.5,BI19*0.25,BJ19,BK19,BL19,BM19,BN19,BO19,BP19,BR19/20,BS19/100,BT19/60,BU19,BV19,BW19,BX19/4,SUM(BY19:CC29)/3,CE19,CG19/3,CI19,CK19,CM19,CO19,CQ19,CR19) -> 5.2 | CU19: =D19 -> DVB
C20: 2 | D20: DVB | O20: =IF(AND(M20<>0,M20<>"m",M20<>"",RIGHT(K20,3)="Lec"),1,IF(AND(M20<>0,M20<>"m",M20<>"",OR(RIGHT(K20,3)="Lab",RIGHT(K20,3)="Tut")),0.5,IF(AND(M20<>0,M20<>"m",M20<>"",RIGHT(K20,2)="TL"),0.75,0))) -> 0 | CU20: =D20 -> DVB
C21: 3 | D21: DVB | O21: =IF(AND(M21<>0,M21<>"m",M21<>"",RIGHT(K21,3)="Lec"),1,IF(AND(M21<>0,M21<>"m",M21<>"",OR(RIGHT(K21,3)="Lab",RIGHT(K21,3)="Tut")),0.5,IF(AND(M21<>0,M21<>"m",M21<>"",RIGHT(K21,2)="TL"),0.75,0))) -> 0 | CU21: =D21 -> DVB
C22: 4 | D22: DVB | O22: =IF(AND(M22<>0,M22<>"m",M22<>"",RIGHT(K22,3)="Lec"),1,IF(AND(M22<>0,M22<>"m",M22<>"",OR(RIGHT(K22,3)="Lab",RIGHT(K22,3)="Tut")),0.5,IF(AND(M22<>0,M22<>"m",M22<>"",RIGHT(K22,2)="TL"),0.75,0))) -> 0 | CU22: =D22 -> DVB
C23: 5 | D23: DVB | O23: =IF(AND(M23<>0,M23<>"m",M23<>"",RIGHT(K23,3)="Lec"),1,IF(AND(M23<>0,M23<>"m",M23<>"",OR(RIGHT(K23,3)="Lab",RIGHT(K23,3)="Tut")),0.5,IF(AND(M23<>0,M23<>"m",M23<>"",RIGHT(K23,2)="TL"),0.75,0))) -> 0 | CU23: =D23 -> DVB
C24: 6 | D24: DVB | O24: =IF(AND(M24<>0,M24<>"m",M24<>"",RIGHT(K24,3)="Lec"),1,IF(AND(M24<>0,M24<>"m",M24<>"",OR(RIGHT(K24,3)="Lab",RIGHT(K24,3)="Tut")),0.5,IF(AND(M24<>0,M24<>"m",M24<>"",RIGHT(K24,2)="TL"),0.75,0))) -> 0 | CU24: =D24 -> DVB
C25: 7 | D25: DVB | O25: =IF(AND(M25>=20,M25<>"m",RIGHT(K25,3)="Lec"),1,IF(AND(M25>=20,M25<>"m",OR(RIGHT(K25,3)="Lab",RIGHT(K25,3)="Tut")),0.5,IF(AND(M25>=20,M25<>"m",RIGHT(K25,2)="TL"),0.75,0))) -> 0 | CU25: =D25 -> DVB
C26: 8 | D26: DVB | O26: =IF(AND(M26>=20,M26<>"m",RIGHT(K26,3)="Lec"),1,IF(AND(M26>=20,M26<>"m",OR(RIGHT(K26,3)="Lab",RIGHT(K26,3)="Tut")),0.5,IF(AND(M26>=20,M26<>"m",RIGHT(K26,2)="TL"),0.75,0))) -> 0 | CU26: =D26 -> DVB
C27: 9 | D27: DVB | O27: =IF(AND(M27>=20,M27<>"m",RIGHT(K27,3)="Lec"),1,IF(AND(M27>=20,M27<>"m",OR(RIGHT(K27,3)="Lab",RIGHT(K27,3)="Tut")),0.5,IF(AND(M27>=20,M27<>"m",RIGHT(K27,2)="TL"),0.75,0))) -> 0 | CU27: =D27 -> DVB
C28: 10 | D28: DVB | O28: =IF(AND(M28>=20,M28<>"m",RIGHT(K28,3)="Lec"),1,IF(AND(M28>=20,M28<>"m",OR(RIGHT(K28,3)="Lab",RIGHT(K28,3)="Tut")),0.5,IF(AND(M28>=20,M28<>"m",RIGHT(K28,2)="TL"),0.75,0))) -> 0 | CU28: =D28 -> DVB
C29: 11 | D29: DVB | O29: =IF(AND(M29<>0,M29<>"m",M29<>"",RIGHT(K29,3)="Lec"),1,IF(AND(M29<>0,M29<>"m",M29<>"",OR(RIGHT(K29,3)="Lab",RIGHT(K29,3)="Tut")),0.5,IF(AND(M29<>0,M29<>"m",M29<>"",RIGHT(K29,2)="TL"),0.75,0))) -> 0 | CU29: =D29 -> DVB
A30: 3 | B30: Ms. Mansi Hedav DOJ: 01/04/2022 MOB: 9408362853 | C30: 1 | D30: MPH | O30: =IF(AND(M30<>0,M30<>"m",M30<>"",RIGHT(K30,3)="Lec"),1,IF(AND(M30<>0,M30<>"m",M30<>"",OR(RIGHT(K30,3)="Lab",RIGHT(K30,3)="Tut")),0.5,IF(AND(M30<>0,M30<>"m",M30<>"",RIGHT(K30,2)="TL"),0.75,0))) -> 0 | P30: =COUNTIF(K30:K40,"TL")*0.75+COUNTIF(K30:K40,"Lec")*1+COUNTIF(K30:K40,"Lab")*0.5 -> 0 | Q30: =SUM((IF(LEFT(K30,1)="E",O30,0)),(IF(LEFT(K31,1)="E",O31,0)),(IF(LEFT(K32,1)="E",O32,0)),(IF(LEFT(K33,1)="E",O33,0)),(IF(LEFT(K34,1)="E",O34,0)),(IF(LEFT(K35,1)="E",O35,0)),(IF(LEFT(K36,1)="E",O36,0)),(IF(LEFT(K37,1)="E",O37,0)),(IF(LEFT(K38,1)="E",O38,0)),(IF(LEFT(K39,1)="E",O39,0)),(IF(LEFT(K40,1)="E",O40,0))) -> 0 | R30: =SUM(IF(M36<20,IF(K36="Plec",-1,IF(K36="PTL",-0.75,IF(K36="Plab",-0.5,0))),0),IF(M37<20,IF(K37="Plec",-1,IF(K37="PTL",-0.75,IF(K37="Plab",-0.5,0))),0),IF(M38<20,IF(K38="Plec",-1,IF(K38="PTL",-0.75,IF(K38="Plab",-0.5,0))),0),IF(M39<20,IF(K39="Plec",-1,IF(K39="PTL",-0.75,IF(K39="Plab",-0.5,0))),0)) -> 0 | S30: =SUM(P30:R40) -> 0 | T30: =SUM(IF(M30="M",IF(OR(K30="lec",K30="plec",K30="slec"),1,IF(OR(K30="lab",K30="plab",K30="slab",K30="tut",K30="ptut",K30="stut"),0.5,IF(OR(K30="TL",K30="pTL",K30="STL"),0.75,0))),0),IF(M31="M",IF(OR(K31="lec",K31="plec",K31="slec"),1,IF(OR(K31="lab",K31="plab",K31="slab",K31="tut",K31="ptut",K31="stut"),0.5,IF(OR(K31="TL",K31="pTL",K31="STL"),0.75,0))),0),IF(M32="M",IF(OR(K32="lec",K32="plec",K32="slec"),1,IF(OR(K32="lab",K32="plab",K32="slab",K32="tut",K32="ptut",K32="stut"),0.5,IF(OR(K32="TL",K32="pTL",K32="STL"),0.75,0))),0),IF(M33="M",IF(OR(K33="lec",K33="plec",K33="slec"),1,IF(OR(K33="lab",K33="plab",K33="slab",K33="tut",K33="ptut",K33="stut"),0.5,IF(OR(K33="TL",K33="pTL",K33="STL"),0.75,0))),0),IF(M34="M",IF(OR(K34="lec",K34="plec",K34="slec"),1,IF(OR(K34="lab",K34="plab",K34="slab",K34="tut",K34="ptut",K34="stut"),0.5,IF(OR(K34="TL",K34="pTL",K34="STL"),0.75,0))),0),IF(M35="M",IF(OR(K35="lec",K35="plec",K35="slec"),1,IF(OR(K35="lab",K35="plab",K35="slab",K35="tut",K35="ptut",K35="stut"),0.5,IF(OR(K35="TL",K35="pTL",K35="STL"),0.75,0))),0),IF(M36="M",IF(OR(K36="lec",K36="plec",K36="slec"),1,IF(OR(K36="lab",K36="plab",K36="slab",K36="tut",K36="ptut",K36="stut"),0.5,IF(OR(K36="TL",K36="pTL",K36="STL"),0.75,0))),0),IF(M37="M",IF(OR(K37="lec",K37="plec",K37="slec"),1,IF(OR(K37="lab",K37="plab",K37="slab",K37="tut",K37="ptut",K37="stut"),0.5,IF(OR(K37="TL",K37="pTL",K37="STL"),0.75,0))),0),IF(M38="M",IF(OR(K38="lec",K38="plec",K38="slec"),1,IF(OR(K38="lab",K38="plab",K38="slab",K38="tut",K38="ptut",K38="stut"),0.5,IF(OR(K38="TL",K38="pTL",K38="STL"),0.75,0))),0),IF(M39="M",IF(OR(K39="lec",K39="plec",K39="slec"),1,IF(OR(K39="lab",K39="plab",K39="slab",K39="tut",K39="ptut",K39="stut"),0.5,IF(OR(K39="TL",K39="pTL",K39="STL"),0.75,0))),0),IF(M40="M",IF(OR(K40="lec",K40="plec",K40="slec"),1,IF(OR(K40="lab",K40="plab",K40="slab",K40="tut",K40="ptut",K40="stut"),0.5,IF(OR(K40="TL",K40="pTL",K40="STL"),0.75,0))),0)) -> 0 | X30: =S30-(T30+U30+V30+W30) -> 0 | Y30: =CONCATENATE(SUM(O30:O40),"(",SUM(O30:O40)-X30,")") -> 0(0) | AP30: =SUM(SUM(O30:O40),SUM(AI30:AI40)/2,AM30) -> 0 | AR30: =AP30*AQ30 -> 0 | AS30: =CT30 -> 4.36 | AT30: =AR30*0.75+AS30*0.25 -> 1.09 | BA30: 1 | BB30: Morning | BC30: 6 | BD30: 104 | BE30: Assigned | BG30: 1 | BJ30: 4 | BQ30: Week-3 less attendance phone call to parent | BR30: 7 | BS30: 1 | CF30: Paper setting of SEM-III -PS - T1 Exam | CJ30: DR count mismatchDR(19, 21), Attendance Sheet(22, 22) | CK30: -1 | CS30: =SUM(IF(AU30<0,ABS(AU30),0),IF(AZ30<0,ABS(AZ30),0),ABS(CI30),ABS(CK30),ABS(CM30),ABS(CO30),ABS(CQ30),ABS(CR30)) -> 1 | CT30: =SUM(AU30,AV30,AW30,AX30/400,AY30,AZ30,BG30,BH30*0.5,BI30*0.25,BJ30,BK30,BL30,BM30,BN30,BO30,BP30,BR30/20,BS30/100,BT30/60,BU30,BV30,BW30,BX30/4,SUM(BY30:CC40)/3,CE30,CG30/3,CI30,CK30,CM30,CO30,CQ30,CR30) -> 4.36 | CU30: =D30 -> MPH
C31: 2 | D31: MPH | O31: =IF(AND(M31<>0,M31<>"m",M31<>"",RIGHT(K31,3)="Lec"),1,IF(AND(M31<>0,M31<>"m",M31<>"",OR(RIGHT(K31,3)="Lab",RIGHT(K31,3)="Tut")),0.5,IF(AND(M31<>0,M31<>"m",M31<>"",RIGHT(K31,2)="TL"),0.75,0))) -> 0 | CU31: =D31 -> MPH
C32: 3 | D32: MPH | O32: =IF(AND(M32<>0,M32<>"m",M32<>"",RIGHT(K32,3)="Lec"),1,IF(AND(M32<>0,M32<>"m",M32<>"",OR(RIGHT(K32,3)="Lab",RIGHT(K32,3)="Tut")),0.5,IF(AND(M32<>0,M32<>"m",M32<>"",RIGHT(K32,2)="TL"),0.75,0))) -> 0 | CU32: =D32 -> MPH
C33: 4 | D33: MPH | O33: =IF(AND(M33<>0,M33<>"m",M33<>"",RIGHT(K33,3)="Lec"),1,IF(AND(M33<>0,M33<>"m",M33<>"",OR(RIGHT(K33,3)="Lab",RIGHT(K33,3)="Tut")),0.5,IF(AND(M33<>0,M33<>"m",M33<>"",RIGHT(K33,2)="TL"),0.75,0))) -> 0 | CU33: =D33 -> MPH
C34: 5 | D34: MPH | O34: =IF(AND(M34<>0,M34<>"m",M34<>"",RIGHT(K34,3)="Lec"),1,IF(AND(M34<>0,M34<>"m",M34<>"",OR(RIGHT(K34,3)="Lab",RIGHT(K34,3)="Tut")),0.5,IF(AND(M34<>0,M34<>"m",M34<>"",RIGHT(K34,2)="TL"),0.75,0))) -> 0 | CU34: =D34 -> MPH
C35: 6 | D35: MPH | O35: =IF(AND(M35<>0,M35<>"m",M35<>"",RIGHT(K35,3)="Lec"),1,IF(AND(M35<>0,M35<>"m",M35<>"",OR(RIGHT(K35,3)="Lab",RIGHT(K35,3)="Tut")),0.5,IF(AND(M35<>0,M35<>"m",M35<>"",RIGHT(K35,2)="TL"),0.75,0))) -> 0 | CU35: =D35 -> MPH
C36: 7 | D36: MPH | O36: =IF(AND(M36>=20,M36<>"m",RIGHT(K36,3)="Lec"),1,IF(AND(M36>=20,M36<>"m",OR(RIGHT(K36,3)="Lab",RIGHT(K36,3)="Tut")),0.5,IF(AND(M36>=20,M36<>"m",RIGHT(K36,2)="TL"),0.75,0))) -> 0 | CU36: =D36 -> MPH
C37: 8 | D37: MPH | O37: =IF(AND(M37>=20,M37<>"m",RIGHT(K37,3)="Lec"),1,IF(AND(M37>=20,M37<>"m",OR(RIGHT(K37,3)="Lab",RIGHT(K37,3)="Tut")),0.5,IF(AND(M37>=20,M37<>"m",RIGHT(K37,2)="TL"),0.75,0))) -> 0 | CU37: =D37 -> MPH
C38: 9 | D38: MPH | O38: =IF(AND(M38>=20,M38<>"m",RIGHT(K38,3)="Lec"),1,IF(AND(M38>=20,M38<>"m",OR(RIGHT(K38,3)="Lab",RIGHT(K38,3)="Tut")),0.5,IF(AND(M38>=20,M38<>"m",RIGHT(K38,2)="TL"),0.75,0))) -> 0 | CU38: =D38 -> MPH
C39: 10 | D39: MPH | O39: =IF(AND(M39>=20,M39<>"m",RIGHT(K39,3)="Lec"),1,IF(AND(M39>=20,M39<>"m",OR(RIGHT(K39,3)="Lab",RIGHT(K39,3)="Tut")),0.5,IF(AND(M39>=20,M39<>"m",RIGHT(K39,2)="TL"),0.75,0))) -> 0 | CU39: =D39 -> MPH
C40: 11 | D40: MPH | O40: =IF(AND(M40<>0,M40<>"m",M40<>"",RIGHT(K40,3)="Lec"),1,IF(AND(M40<>0,M40<>"m",M40<>"",OR(RIGHT(K40,3)="Lab",RIGHT(K40,3)="Tut")),0.5,IF(AND(M40<>0,M40<>"m",M40<>"",RIGHT(K40,2)="TL"),0.75,0))) -> 0 | CU40: =D40 -> MPH
A41: 4 | B41: Mr.Mehul Kodiya DOJ: 16/06/2015 MOB: 9998650442 | C41: 1 | D41: MVK | O41: =IF(AND(M41<>0,M41<>"m",M41<>"",RIGHT(K41,3)="Lec"),1,IF(AND(M41<>0,M41<>"m",M41<>"",OR(RIGHT(K41,3)="Lab",RIGHT(K41,3)="Tut")),0.5,IF(AND(M41<>0,M41<>"m",M41<>"",RIGHT(K41,2)="TL"),0.75,0))) -> 0 | P41: =COUNTIF(K41:K51,"TL")*0.75+COUNTIF(K41:K51,"Lec")*1+COUNTIF(K41:K51,"Lab")*0.5 -> 0 | Q41: =SUM((IF(LEFT(K41,1)="E",O41,0)),(IF(LEFT(K42,1)="E",O42,0)),(IF(LEFT(K43,1)="E",O43,0)),(IF(LEFT(K44,1)="E",O44,0)),(IF(LEFT(K45,1)="E",O45,0)),(IF(LEFT(K46,1)="E",O46,0)),(IF(LEFT(K47,1)="E",O47,0)),(IF(LEFT(K48,1)="E",O48,0)),(IF(LEFT(K49,1)="E",O49,0)),(IF(LEFT(K50,1)="E",O50,0)),(IF(LEFT(K51,1)="E",O51,0))) -> 0 | R41: =SUM(IF(M47<20,IF(K47="Plec",-1,IF(K47="PTL",-0.75,IF(K47="Plab",-0.5,0))),0),IF(M48<20,IF(K48="Plec",-1,IF(K48="PTL",-0.75,IF(K48="Plab",-0.5,0))),0),IF(M49<20,IF(K49="Plec",-1,IF(K49="PTL",-0.75,IF(K49="Plab",-0.5,0))),0),IF(M50<20,IF(K50="Plec",-1,IF(K50="PTL",-0.75,IF(K50="Plab",-0.5,0))),0)) -> 0 | S41: =SUM(P41:R51) -> 0 | T41: =SUM(IF(M41="M",IF(OR(K41="lec",K41="plec",K41="slec"),1,IF(OR(K41="lab",K41="plab",K41="slab",K41="tut",K41="ptut",K41="stut"),0.5,IF(OR(K41="TL",K41="pTL",K41="STL"),0.75,0))),0),IF(M42="M",IF(OR(K42="lec",K42="plec",K42="slec"),1,IF(OR(K42="lab",K42="plab",K42="slab",K42="tut",K42="ptut",K42="stut"),0.5,IF(OR(K42="TL",K42="pTL",K42="STL"),0.75,0))),0),IF(M43="M",IF(OR(K43="lec",K43="plec",K43="slec"),1,IF(OR(K43="lab",K43="plab",K43="slab",K43="tut",K43="ptut",K43="stut"),0.5,IF(OR(K43="TL",K43="pTL",K43="STL"),0.75,0))),0),IF(M44="M",IF(OR(K44="lec",K44="plec",K44="slec"),1,IF(OR(K44="lab",K44="plab",K44="slab",K44="tut",K44="ptut",K44="stut"),0.5,IF(OR(K44="TL",K44="pTL",K44="STL"),0.75,0))),0),IF(M45="M",IF(OR(K45="lec",K45="plec",K45="slec"),1,IF(OR(K45="lab",K45="plab",K45="slab",K45="tut",K45="ptut",K45="stut"),0.5,IF(OR(K45="TL",K45="pTL",K45="STL"),0.75,0))),0),IF(M46="M",IF(OR(K46="lec",K46="plec",K46="slec"),1,IF(OR(K46="lab",K46="plab",K46="slab",K46="tut",K46="ptut",K46="stut"),0.5,IF(OR(K46="TL",K46="pTL",K46="STL"),0.75,0))),0),IF(M47="M",IF(OR(K47="lec",K47="plec",K47="slec"),1,IF(OR(K47="lab",K47="plab",K47="slab",K47="tut",K47="ptut",K47="stut"),0.5,IF(OR(K47="TL",K47="pTL",K47="STL"),0.75,0))),0),IF(M48="M",IF(OR(K48="lec",K48="plec",K48="slec"),1,IF(OR(K48="lab",K48="plab",K48="slab",K48="tut",K48="ptut",K48="stut"),0.5,IF(OR(K48="TL",K48="pTL",K48="STL"),0.75,0))),0),IF(M49="M",IF(OR(K49="lec",K49="plec",K49="slec"),1,IF(OR(K49="lab",K49="plab",K49="slab",K49="tut",K49="ptut",K49="stut"),0.5,IF(OR(K49="TL",K49="pTL",K49="STL"),0.75,0))),0),IF(M50="M",IF(OR(K50="lec",K50="plec",K50="slec"),1,IF(OR(K50="lab",K50="plab",K50="slab",K50="tut",K50="ptut",K50="stut"),0.5,IF(OR(K50="TL",K50="pTL",K50="STL"),0.75,0))),0),IF(M51="M",IF(OR(K51="lec",K51="plec",K51="slec"),1,IF(OR(K51="lab",K51="plab",K51="slab",K51="tut",K51="ptut",K51="stut"),0.5,IF(OR(K51="TL",K51="pTL",K51="STL"),0.75,0))),0)) -> 0 | X41: =S41-(T41+U41+V41+W41) -> 0 | Y41: =CONCATENATE(SUM(O41:O51),"(",SUM(O41:O51)-X41,")") -> 0(0) | AP41: =SUM(SUM(O41:O51),SUM(AI41:AI51)/2,AM41) -> 0 | AR41: =AP41*AQ41 -> 0 | AS41: =CT41 -> 5.75 | AT41: =AR41*0.75+AS41*0.25 -> 1.4375 | BI41: 6 | BJ41: 4 | BQ41: Week-3 Attendance less than 75% of sem-3 | BR41: 5 | BS41: 0 | CF41: Paper Setting of SEM-III FCSP-1 T1 Exam | CS41: =SUM(IF(AU41<0,ABS(AU41),0),IF(AZ41<0,ABS(AZ41),0),ABS(CI41),ABS(CK41),ABS(CM41),ABS(CO41),ABS(CQ41),ABS(CR41)) -> 0 | CT41: =SUM(AU41,AV41,AW41,AX41/400,AY41,AZ41,BG41,BH41*0.5,BI41*0.25,BJ41,BK41,BL41,BM41,BN41,BO41,BP41,BR41/20,BS41/100,BT41/60,BU41,BV41,BW41,BX41/4,SUM(BY41:CC51)/3,CE41,CG41/3,CI41,CK41,CM41,CO41,CQ41,CR41) -> 5.75 | CU41: =D41 -> MVK
...

Sheet 22 Oct Tues
A1: =CONCATENATE("DAILY REPORT DATE : ",MID(CELL("filename",A1),FIND("]",CELL("filename",A1),1)+1,255)) -> #VALUE! | AU1: =A1 -> #VALUE!
A3: COLLEGE NAME : L.J. INSTITUTE OF ENGINEERING AND TECHNOLOGY DEPARTMENT NAME : SY4(CST CS&IT) YEAR : 2024-25 SEMESTER : III | AU3: =A3 -> COLLEGE NAME : L.J. INSTITUTE OF ENGINEERING AND TECHNOLOGY DEPARTMENT NAME : SY4(CST CS&IT) YEAR : 2024-25 SEMESTER : III
A4: TEACHING SECTION | AU4: NON TEACHING SECTION | CH4: HOD SECTION
A5: LECTURE DETAILS | AA5: Difficulty solving or if attendance is less than 5 /Whatsapp Doubt Solving in official group / Students details whose Home Visit was done / PTM (Roll No,Name, Contact No.) (H) | AJ5: Project / Dissertation/Design Engineering Load (Enter only if Answer is given by Guide of the technical query) | AP5: Total Teaching Credits (A) | AQ5: Teaching Feedback (B) | AR5: Effective Teaching Credit C= A * B | AS5: NT Total Credits (D) Refer from NT Section | AT5: Final Teaching + Non Teaching Credit E =C*0.75+D*0.25 | AU5: Once in a Semester | AY5: Load Adjustment Done | AZ5: AttendanceSubmission.If Not submitted | BA5: Examination | BP5: PARENTS INTERACTION | BV5: SIF Credit | BX5: Extra Activity
A6: Sr No | B6: Name-DOJ-Mobile No. | C6: Lec. No | D6: Faculty Initials | E6: Lecture Details | M6: No. of Students Present | N6: Total Students | O6: Effective Load | P6: Today's Eff.Load Alloted as per TT | Q6: Extra Load | R6: Merged Load (If student in proxy batch < 20, mention (-1) for 2 hrs Lab or (-1.5) for 2 hrs TL | S6: Overall Today's Effective Load | T6: Today's Eff. Mass bunk | U6: Today's Eff.load cancel bcz of Holiday | V6: Today's Eff load cancel bcz of Specific reason | W6: Today's Eff load cancel bcz no adjustment was possible | X6: Today's Total Eff Load Expected from Faculty | Y6: Today's Eff.Load Taken | Z6: Comment for dummy column name C,D,E (Holiday, or load cacnelled details) | AU6: Submission of Subject Folder (LP, QB,MSE Syllabus, Ques Paper etc) Enter Credit=0 if done on time, Else (-1) daily until submitted | AV6: Timetable Preparation Credit as per GI | AW6: No.of Project/Dissertation Groups handled (To be entered at the end of semester) | AX6: No.of Marks Entry in GTU Portal | BA6: Supervision during College Exam | BJ6: Paper Setting | BK6: Paper Solution | BL6: Paper Evaluation | BO6: Paper Showing | BP6: Home Visit Credit & Enter details in (H-Teaching Section) (Credit =1 - Meeting with Mother Credit = 1.5 - Meeting with Father) | BQ6: No. of Phone Calls and entered in SIF | BT6: No. of SMS done | BU6: Personal Discussion with parents in Institute (0.25 credit per student) | BV6: Enter Credit for Personal Information in Page 1 and Page 2 | BW6: Enter credit for any entry work done in SIF | BX6: Extra Activity in hours as per General Instructions. | CF6: Not Defined as per General Instruction (Enter in terms of Hrs) | CH6: Leave Status | CJ6: Error in Work done | CL6: Delay in Work Done | CN6: Any other HOD Comment | CP6: Description of Work refused by faculty or done after doing arguments with HOD | CQ6: Enter credit if Faculty Refusd to do work given by HOD. Credit = (-5) | CR6: Enter credit if Faculty does work after doing arguments with HOD. Credit = (-2) | CS6: HOD Positive Credit and Faculty Negative Credit | CT6: Total NT Credits
E7: Course (UG/PG) | F7: Dept | G7: SEM (Only Roman Number) | H7: Div | I7: Batch | J7: Sub. | K7: Lec/ Lab/Tut/ELec/ELab/ETut/PLec/Plab/PTut/SLec/SLab/Stut/TL/ETL/STL/PTL | L7: Faculty Initials for Proxy Lecture Only a) Faculty who was given the proxy b) Faculty whose proxy was taken | O7: G | P7: A1 | Q7: A2 | R7: A3 | S7: A=A1+A2+A3 | T7: B | U7: C | V7: D | W7: E | X7: F= A-B-C-D-E | Y7: G(G-F) | AA7: Enter Purpose Short Form DS - Difficulty Solving HV - Home Visit WA - Whatsapp AL5 - Attendance Less than 5 PTM - Parents Teacher Meeting at Institute | AB7: Sem | AC7: Div | AD7: Roll No | AE7: Name | AF7: Mobile | AG7: No.of Students Present | AH7: Time (Only for difficulty solving) | AI7: Total No.of Hours (Only for difficulty solving) | AJ7: Group Code (Format : UG/PG_Branch_SEMNo_GroupNo Ex : UG_ME_SEM4_8) | AK7: Technical Question asked by student | AL7: Date & Time (Start time : End Time) | AM7: Duration in hours | AN7: Name of the Student who asked the question | AO7: Mobile No of the student | AY7: (Credit 0.1 for 1 effective hour of load adjustment done) | AZ7: Enter (-1) upto each day of delay else 0 if submitted on time | BA7: Today's No of Assign Supervision | BB7: Session (Morning / Afternoon) | BC7: Block No | BD7: Room No | BE7: Assigned /Proxy / Swap | BF7: Faculty Short Name whose Proxy is taken / with whom Swapping is done | BG7: Today's taken Supervision (MSE) | BH7: Today's taken Supervision (REM) | BI7: Today's No of blocks handle by MSE exam coordinator | BJ7: Credit (MSE I,II =0.5*no of papers, REM =0.25*no of papers) | BK7: Credit 1 for preparing 50% solution with detailing) Enter credit | BL7: Enter Credit of MSE Paper Evaluated Section A and B both (1 credit =15 papers) | BM7: Enter Credit of MSE Paper Evaluated-Any one Section A or B (1 credit =30 papers) | BN7: Enter Credit of Rem Paper Evaluated (1 credit =30 papers) | BO7: No. of Class | BQ7: Phone Call Description | BR7: Received Phone Call | BS7: Not Received Phone Call | BX7: Sports | BY7: Cultural | BZ7: GTU Related Work Only for GTU Coordinators | CA7: COE | CB7: Techventure | CC7: Any Technical Events | CD7: Any Other Activity Description | CE7: Total Credit | CF7: Activity Description | CG7: Total hr | CH7: Leave Taken | CI7: Leave Credit (Enter Negative Value) | CJ7: Description of Error done | CK7: Error Credit (Enter only Negative Value of Credit) | CL7: Description of Delay done | CM7: No. of Days of late submission (Enter only Negative Value of Credit) | CN7: Description | CO7: Credit ( Enter Negative value if comment for negative credit)
A8: 1 | B8: Ms. Sneha Shah DOJ: 9/7/2012 MOB: 9067822170 | C8: 1 | D8: STS | O8: =IF(AND(M8<>0,M8<>"m",M8<>"",RIGHT(K8,3)="Lec"),1,IF(AND(M8<>0,M8<>"m",M8<>"",OR(RIGHT(K8,3)="Lab",RIGHT(K8,3)="Tut")),0.5,IF(AND(M8<>0,M8<>"m",M8<>"",RIGHT(K8,2)="TL"),0.75,0))) -> 0 | P8: =COUNTIF(K8:K18,"TL")*0.75+COUNTIF(K8:K18,"Lec")*1+COUNTIF(K8:K18,"Lab")*0.5 -> 0 | Q8: =SUM((IF(LEFT(K8,1)="E",O8,0)),(IF(LEFT(K9,1)="E",O9,0)),(IF(LEFT(K10,1)="E",O10,0)),(IF(LEFT(K11,1)="E",O11,0)),(IF(LEFT(K12,1)="E",O12,0)),(IF(LEFT(K13,1)="E",O13,0)),(IF(LEFT(K14,1)="E",O14,0)),(IF(LEFT(K15,1)="E",O15,0)),(IF(LEFT(K16,1)="E",O16,0)),(IF(LEFT(K17,1)="E",O17,0)),(IF(LEFT(K18,1)="E",O18,0))) -> 0 | R8: =SUM(IF(M14<20,IF(K14="Plec",-1,IF(K14="PTL",-0.75,IF(K14="Plab",-0.5,0))),0),IF(M15<20,IF(K15="Plec",-1,IF(K15="PTL",-0.75,IF(K15="Plab",-0.5,0))),0),IF(M16<20,IF(K16="Plec",-1,IF(K16="PTL",-0.75,IF(K16="Plab",-0.5,0))),0),IF(M17<20,IF(K17="Plec",-1,IF(K17="PTL",-0.75,IF(K17="Plab",-0.5,0))),0)) -> 0 | S8: =SUM(P8:R18) -> 0 | T8: =SUM(IF(M8="M",IF(OR(K8="lec",K8="plec",K8="slec"),1,IF(OR(K8="lab",K8="plab",K8="slab",K8="tut",K8="ptut",K8="stut"),0.5,IF(OR(K8="TL",K8="pTL",K8="STL"),0.75,0))),0),IF(M9="M",IF(OR(K9="lec",K9="plec",K9="slec"),1,IF(OR(K9="lab",K9="plab",K9="slab",K9="tut",K9="ptut",K9="stut"),0.5,IF(OR(K9="TL",K9="pTL",K9="STL"),0.75,0))),0),IF(M10="M",IF(OR(K10="lec",K10="plec",K10="slec"),1,IF(OR(K10="lab",K10="plab",K10="slab",K10="tut",K10="ptut",K10="stut"),0.5,IF(OR(K10="TL",K10="pTL",K10="STL"),0.75,0))),0),IF(M11="M",IF(OR(K11="lec",K11="plec",K11="slec"),1,IF(OR(K11="lab",K11="plab",K11="slab",K11="tut",K11="ptut",K11="stut"),0.5,IF(OR(K11="TL",K11="pTL",K11="STL"),0.75,0))),0),IF(M12="M",IF(OR(K12="lec",K12="plec",K12="slec"),1,IF(OR(K12="lab",K12="plab",K12="slab",K12="tut",K12="ptut",K12="stut"),0.5,IF(OR(K12="TL",K12="pTL",K12="STL"),0.75,0))),0),IF(M13="M",IF(OR(K13="lec",K13="plec",K13="slec"),1,IF(OR(K13="lab",K13="plab",K13="slab",K13="tut",K13="ptut",K13="stut"),0.5,IF(OR(K13="TL",K13="pTL",K13="STL"),0.75,0))),0),IF(M14="M",IF(OR(K14="lec",K14="plec",K14="slec"),1,IF(OR(K14="lab",K14="plab",K14="slab",K14="tut",K14="ptut",K14="stut"),0.5,IF(OR(K14="TL",K14="pTL",K14="STL"),0.75,0))),0),IF(M15="M",IF(OR(K15="lec",K15="plec",K15="slec"),1,IF(OR(K15="lab",K15="plab",K15="slab",K15="tut",K15="ptut",K15="stut"),0.5,IF(OR(K15="TL",K15="pTL",K15="STL"),0.75,0))),0),IF(M16="M",IF(OR(K16="lec",K16="plec",K16="slec"),1,IF(OR(K16="lab",K16="plab",K16="slab",K16="tut",K16="ptut",K16="stut"),0.5,IF(OR(K16="TL",K16="pTL",K16="STL"),0.75,0))),0),IF(M17="M",IF(OR(K17="lec",K17="plec",K17="slec"),1,IF(OR(K17="lab",K17="plab",K17="slab",K17="tut",K17="ptut",K17="stut"),0.5,IF(OR(K17="TL",K17="pTL",K17="STL"),0.75,0))),0),IF(M18="M",IF(OR(K18="lec",K18="plec",K18="slec"),1,IF(OR(K18="lab",K18="plab",K18="slab",K18="tut",K18="ptut",K18="stut"),0.5,IF(OR(K18="TL",K18="pTL",K18="STL"),0.75,0))),0)) -> 0 | X8: =S8-(T8+U8+V8+W8) -> 0 | Y8: =CONCATENATE(SUM(O8:O18),"(",SUM(O8:O18)-X8,")") -> 0(0) | AP8: =SUM(SUM(O8:O18),SUM(AI8:AI18)/2,AM8) -> 0 | AR8: =AP8*AQ8 -> 0 | AS8: =CT8 -> 0 | AT8: =AR8*0.75+AS8*0.25 -> 0 | CS8: =SUM(CS19:CS305) -> 0 | CT8: =SUM(AU8,AV8,AW8,AX8/400,AY8,AZ8,BG8,BH8*0.5,BI8*0.25,BJ8,BK8,BL8,BM8,BN8,BO8,BP8,BR8/20,BS8/100,BT8/60,BU8,BV8,BW8,BX8/4,SUM(BY8:CC18)/3,CE8,CG8/3,CI8,CK8,CM8,CO8,CQ8,CR8) -> 0 | CU8: =D8 -> STS
C9: 2 | D9: STS | O9: =IF(AND(M9<>0,M9<>"m",M9<>"",RIGHT(K9,3)="Lec"),1,IF(AND(M9<>0,M9<>"m",M9<>"",OR(RIGHT(K9,3)="Lab",RIGHT(K9,3)="Tut")),0.5,IF(AND(M9<>0,M9<>"m",M9<>"",RIGHT(K9,2)="TL"),0.75,0))) -> 0 | CU9: =D9 -> STS
C10: 3 | D10: STS | O10: =IF(AND(M10<>0,M10<>"m",M10<>"",RIGHT(K10,3)="Lec"),1,IF(AND(M10<>0,M10<>"m",M10<>"",OR(RIGHT(K10,3)="Lab",RIGHT(K10,3)="Tut")),0.5,IF(AND(M10<>0,M10<>"m",M10<>"",RIGHT(K10,2)="TL"),0.75,0))) -> 0 | CU10: =D10 -> STS
C11: 4 | D11: STS | O11: =IF(AND(M11<>0,M11<>"m",M11<>"",RIGHT(K11,3)="Lec"),1,IF(AND(M11<>0,M11<>"m",M11<>"",OR(RIGHT(K11,3)="Lab",RIGHT(K11,3)="Tut")),0.5,IF(AND(M11<>0,M11<>"m",M11<>"",RIGHT(K11,2)="TL"),0.75,0))) -> 0 | CU11: =D11 -> STS
C12: 5 | D12: STS | O12: =IF(AND(M12<>0,M12<>"m",M12<>"",RIGHT(K12,3)="Lec"),1,IF(AND(M12<>0,M12<>"m",M12<>"",OR(RIGHT(K12,3)="Lab",RIGHT(K12,3)="Tut")),0.5,IF(AND(M12<>0,M12<>"m",M12<>"",RIGHT(K12,2)="TL"),0.75,0))) -> 0 | CU12: =D12 -> STS
C13: 6 | D13: STS | O13: =IF(AND(M13<>0,M13<>"m",M13<>"",RIGHT(K13,3)="Lec"),1,IF(AND(M13<>0,M13<>"m",M13<>"",OR(RIGHT(K13,3)="Lab",RIGHT(K13,3)="Tut")),0.5,IF(AND(M13<>0,M13<>"m",M13<>"",RIGHT(K13,2)="TL"),0.75,0))) -> 0 | CU13: =D13 -> STS
C14: 7 | D14: STS | O14: =IF(AND(M14>=20,M14<>"m",RIGHT(K14,3)="Lec"),1,IF(AND(M14>=20,M14<>"m",OR(RIGHT(K14,3)="Lab",RIGHT(K14,3)="Tut")),0.5,IF(AND(M14>=20,M14<>"m",RIGHT(K14,2)="TL"),0.75,0))) -> 0 | CU14: =D14 -> STS
C15: 8 | D15: STS | O15: =IF(AND(M15>=20,M15<>"m",RIGHT(K15,3)="Lec"),1,IF(AND(M15>=20,M15<>"m",OR(RIGHT(K15,3)="Lab",RIGHT(K15,3)="Tut")),0.5,IF(AND(M15>=20,M15<>"m",RIGHT(K15,2)="TL"),0.75,0))) -> 0 | CU15: =D15 -> STS
C16: 9 | D16: STS | O16: =IF(AND(M16>=20,M16<>"m",RIGHT(K16,3)="Lec"),1,IF(AND(M16>=20,M16<>"m",OR(RIGHT(K16,3)="Lab",RIGHT(K16,3)="Tut")),0.5,IF(AND(M16>=20,M16<>"m",RIGHT(K16,2)="TL"),0.75,0))) -> 0 | CU16: =D16 -> STS
C17: 10 | D17: STS | O17: =IF(AND(M17>=20,M17<>"m",RIGHT(K17,3)="Lec"),1,IF(AND(M17>=20,M17<>"m",OR(RIGHT(K17,3)="Lab",RIGHT(K17,3)="Tut")),0.5,IF(AND(M17>=20,M17<>"m",RIGHT(K17,2)="TL"),0.75,0))) -> 0 | CU17: =D17 -> STS
C18: 11 | D18: STS | O18: =IF(AND(M18<>0,M18<>"m",M18<>"",RIGHT(K18,3)="Lec"),1,IF(AND(M18<>0,M18<>"m",M18<>"",OR(RIGHT(K18,3)="Lab",RIGHT(K18,3)="Tut")),0.5,IF(AND(M18<>0,M18<>"m",M18<>"",RIGHT(K18,2)="TL"),0.75,0))) -> 0 | CU18: =D18 -> STS
A19: 2 | B19: Mr.Darshan Bhatt DOJ: 20/07/2022 MOB: 7227888101 | C19: 1 | D19: DVB | O19: =IF(AND(M19<>0,M19<>"m",M19<>"",RIGHT(K19,3)="Lec"),1,IF(AND(M19<>0,M19<>"m",M19<>"",OR(RIGHT(K19,3)="Lab",RIGHT(K19,3)="Tut")),0.5,IF(AND(M19<>0,M19<>"m",M19<>"",RIGHT(K19,2)="TL"),0.75,0))) -> 0 | P19: =COUNTIF(K19:K29,"TL")*0.75+COUNTIF(K19:K29,"Lec")*1+COUNTIF(K19:K29,"Lab")*0.5 -> 0 | Q19: =SUM((IF(LEFT(K19,1)="E",O19,0)),(IF(LEFT(K20,1)="E",O20,0)),(IF(LEFT(K21,1)="E",O21,0)),(IF(LEFT(K22,1)="E",O22,0)),(IF(LEFT(K23,1)="E",O23,0)),(IF(LEFT(K24,1)="E",O24,0)),(IF(LEFT(K25,1)="E",O25,0)),(IF(LEFT(K26,1)="E",O26,0)),(IF(LEFT(K27,1)="E",O27,0)),(IF(LEFT(K28,1)="E",O28,0)),(IF(LEFT(K29,1)="E",O29,0))) -> 0 | R19: =SUM(IF(M25<20,IF(K25="Plec",-1,IF(K25="PTL",-0.75,IF(K25="Plab",-0.5,0))),0),IF(M26<20,IF(K26="Plec",-1,IF(K26="PTL",-0.75,IF(K26="Plab",-0.5,0))),0),IF(M27<20,IF(K27="Plec",-1,IF(K27="PTL",-0.75,IF(K27="Plab",-0.5,0))),0),IF(M28<20,IF(K28="Plec",-1,IF(K28="PTL",-0.75,IF(K28="Plab",-0.5,0))),0)) -> 0 | S19: =SUM(P19:R29) -> 0 | T19: =SUM(IF(M19="M",IF(OR(K19="lec",K19="plec",K19="slec"),1,IF(OR(K19="lab",K19="plab",K19="slab",K19="tut",K19="ptut",K19="stut"),0.5,IF(OR(K19="TL",K19="pTL",K19="STL"),0.75,0))),0),IF(M20="M",IF(OR(K20="lec",K20="plec",K20="slec"),1,IF(OR(K20="lab",K20="plab",K20="slab",K20="tut",K20="ptut",K20="stut"),0.5,IF(OR(K20="TL",K20="pTL",K20="STL"),0.75,0))),0),IF(M21="M",IF(OR(K21="lec",K21="plec",K21="slec"),1,IF(OR(K21="lab",K21="plab",K21="slab",K21="tut",K21="ptut",K21="stut"),0.5,IF(OR(K21="TL",K21="pTL",K21="STL"),0.75,0))),0),IF(M22="M",IF(OR(K22="lec",K22="plec",K22="slec"),1,IF(OR(K22="lab",K22="plab",K22="slab",K22="tut",K22="ptut",K22="stut"),0.5,IF(OR(K22="TL",K22="pTL",K22="STL"),0.75,0))),0),IF(M23="M",IF(OR(K23="lec",K23="plec",K23="slec"),1,IF(OR(K23="lab",K23="plab",K23="slab",K23="tut",K23="ptut",K23="stut"),0.5,IF(OR(K23="TL",K23="pTL",K23="STL"),0.75,0))),0),IF(M24="M",IF(OR(K24="lec",K24="plec",K24="slec"),1,IF(OR(K24="lab",K24="plab",K24="slab",K24="tut",K24="ptut",K24="stut"),0.5,IF(OR(K24="TL",K24="pTL",K24="STL"),0.75,0))),0),IF(M25="M",IF(OR(K25="lec",K25="plec",K25="slec"),1,IF(OR(K25="lab",K25="plab",K25="slab",K25="tut",K25="ptut",K25="stut"),0.5,IF(OR(K25="TL",K25="pTL",K25="STL"),0.75,0))),0),IF(M26="M",IF(OR(K26="lec",K26="plec",K26="slec"),1,IF(OR(K26="lab",K26="plab",K26="slab",K26="tut",K26="ptut",K26="stut"),0.5,IF(OR(K26="TL",K26="pTL",K26="STL"),0.75,0))),0),IF(M27="M",IF(OR(K27="lec",K27="plec",K27="slec"),1,IF(OR(K27="lab",K27="plab",K27="slab",K27="tut",K27="ptut",K27="stut"),0.5,IF(OR(K27="TL",K27="pTL",K27="STL"),0.75,0))),0),IF(M28="M",IF(OR(K28="lec",K28="plec",K28="slec"),1,IF(OR(K28="lab",K28="plab",K28="slab",K28="tut",K28="ptut",K28="stut"),0.5,IF(OR(K28="TL",K28="pTL",K28="STL"),0.75,0))),0),IF(M29="M",IF(OR(K29="lec",K29="plec",K29="slec"),1,IF(OR(K29="lab",K29="plab",K29="slab",K29="tut",K29="ptut",K29="stut"),0.5,IF(OR(K29="TL",K29="pTL",K29="STL"),0.75,0))),0)) -> 0 | X19: =S19-(T19+U19+V19+W19) -> 0 | Y19: =CONCATENATE(SUM(O19:O29),"(",SUM(O19:O29)-X19,")") -> 0(0) | AP19: =SUM(SUM(O19:O29),SUM(AI19:AI29)/2,AM19) -> 0 | AR19: =AP19*AQ19 -> 0 | AS19: =CT19 -> 0.35 | AT19: =AR19*0.75+AS19*0.25 -> 0.0875 | BQ19: Phone call to parent for failed students in T1-PS Exam | BR19: 7 | BS19: 0 | CS19: =SUM(IF(AU19<0,ABS(AU19),0),IF(AZ19<0,ABS(AZ19),0),ABS(CI19),ABS(CK19),ABS(CM19),ABS(CO19),ABS(CQ19),ABS(CR19)) -> 0 | CT19: =SUM(AU19,AV19,AW19,AX19/400,AY19,AZ19,BG19,BH19*0.5,BI19*0.25,BJ19,BK19,BL19,BM19,BN19,BO19,BP19,BR19/20,BS19/100,BT19/60,BU19,BV19,BW19,BX19/4,SUM(BY19:CC29)/3,CE19,CG19/3,CI19,CK19,CM19,CO19,CQ19,CR19) -> 0.35 | CU19: =D19 -> DVB
C20: 2 | D20: DVB | O20: =IF(AND(M20<>0,M20<>"m",M20<>"",RIGHT(K20,3)="Lec"),1,IF(AND(M20<>0,M20<>"m",M20<>"",OR(RIGHT(K20,3)="Lab",RIGHT(K20,3)="Tut")),0.5,IF(AND(M20<>0,M20<>"m",M20<>"",RIGHT(K20,2)="TL"),0.75,0))) -> 0 | CU20: =D20 -> DVB
C21: 3 | D21: DVB | O21: =IF(AND(M21<>0,M21<>"m",M21<>"",RIGHT(K21,3)="Lec"),1,IF(AND(M21<>0,M21<>"m",M21<>"",OR(RIGHT(K21,3)="Lab",RIGHT(K21,3)="Tut")),0.5,IF(AND(M21<>0,M21<>"m",M21<>"",RIGHT(K21,2)="TL"),0.75,0))) -> 0 | CU21: =D21 -> DVB
C22: 4 | D22: DVB | O22: =IF(AND(M22<>0,M22<>"m",M22<>"",RIGHT(K22,3)="Lec"),1,IF(AND(M22<>0,M22<>"m",M22<>"",OR(RIGHT(K22,3)="Lab",RIGHT(K22,3)="Tut")),0.5,IF(AND(M22<>0,M22<>"m",M22<>"",RIGHT(K22,2)="TL"),0.75,0))) -> 0 | CU22: =D22 -> DVB
C23: 5 | D23: DVB | O23: =IF(AND(M23<>0,M23<>"m",M23<>"",RIGHT(K23,3)="Lec"),1,IF(AND(M23<>0,M23<>"m",M23<>"",OR(RIGHT(K23,3)="Lab",RIGHT(K23,3)="Tut")),0.5,IF(AND(M23<>0,M23<>"m",M23<>"",RIGHT(K23,2)="TL"),0.75,0))) -> 0 | CU23: =D23 -> DVB
C24: 6 | D24: DVB | O24: =IF(AND(M24<>0,M24<>"m",M24<>"",RIGHT(K24,3)="Lec"),1,IF(AND(M24<>0,M24<>"m",M24<>"",OR(RIGHT(K24,3)="Lab",RIGHT(K24,3)="Tut")),0.5,IF(AND(M24<>0,M24<>"m",M24<>"",RIGHT(K24,2)="TL"),0.75,0))) -> 0 | CU24: =D24 -> DVB
C25: 7 | D25: DVB | O25: =IF(AND(M25>=20,M25<>"m",RIGHT(K25,3)="Lec"),1,IF(AND(M25>=20,M25<>"m",OR(RIGHT(K25,3)="Lab",RIGHT(K25,3)="Tut")),0.5,IF(AND(M25>=20,M25<>"m",RIGHT(K25,2)="TL"),0.75,0))) -> 0 | CU25: =D25 -> DVB
C26: 8 | D26: DVB | O26: =IF(AND(M26>=20,M26<>"m",RIGHT(K26,3)="Lec"),1,IF(AND(M26>=20,M26<>"m",OR(RIGHT(K26,3)="Lab",RIGHT(K26,3)="Tut")),0.5,IF(AND(M26>=20,M26<>"m",RIGHT(K26,2)="TL"),0.75,0))) -> 0 | CU26: =D26 -> DVB
C27: 9 | D27: DVB | O27: =IF(AND(M27>=20,M27<>"m",RIGHT(K27,3)="Lec"),1,IF(AND(M27>=20,M27<>"m",OR(RIGHT(K27,3)="Lab",RIGHT(K27,3)="Tut")),0.5,IF(AND(M27>=20,M27<>"m",RIGHT(K27,2)="TL"),0.75,0))) -> 0 | CU27: =D27 -> DVB
C28: 10 | D28: DVB | O28: =IF(AND(M28>=20,M28<>"m",RIGHT(K28,3)="Lec"),1,IF(AND(M28>=20,M28<>"m",OR(RIGHT(K28,3)="Lab",RIGHT(K28,3)="Tut")),0.5,IF(AND(M28>=20,M28<>"m",RIGHT(K28,2)="TL"),0.75,0))) -> 0 | CU28: =D28 -> DVB
C29: 11 | D29: DVB | O29: =IF(AND(M29<>0,M29<>"m",M29<>"",RIGHT(K29,3)="Lec"),1,IF(AND(M29<>0,M29<>"m",M29<>"",OR(RIGHT(K29,3)="Lab",RIGHT(K29,3)="Tut")),0.5,IF(AND(M29<>0,M29<>"m",M29<>"",RIGHT(K29,2)="TL"),0.75,0))) -> 0 | CU29: =D29 -> DVB
A30: 3 | B30: Ms. Mansi Hedav DOJ: 01/04/2022 MOB: 9408362853 | C30: 1 | D30: MPH | O30: =IF(AND(M30<>0,M30<>"m",M30<>"",RIGHT(K30,3)="Lec"),1,IF(AND(M30<>0,M30<>"m",M30<>"",OR(RIGHT(K30,3)="Lab",RIGHT(K30,3)="Tut")),0.5,IF(AND(M30<>0,M30<>"m",M30<>"",RIGHT(K30,2)="TL"),0.75,0))) -> 0 | P30: =COUNTIF(K30:K40,"TL")*0.75+COUNTIF(K30:K40,"Lec")*1+COUNTIF(K30:K40,"Lab")*0.5 -> 0 | Q30: =SUM((IF(LEFT(K30,1)="E",O30,0)),(IF(LEFT(K31,1)="E",O31,0)),(IF(LEFT(K32,1)="E",O32,0)),(IF(LEFT(K33,1)="E",O33,0)),(IF(LEFT(K34,1)="E",O34,0)),(IF(LEFT(K35,1)="E",O35,0)),(IF(LEFT(K36,1)="E",O36,0)),(IF(LEFT(K37,1)="E",O37,0)),(IF(LEFT(K38,1)="E",O38,0)),(IF(LEFT(K39,1)="E",O39,0)),(IF(LEFT(K40,1)="E",O40,0))) -> 0 | R30: =SUM(IF(M36<20,IF(K36="Plec",-1,IF(K36="PTL",-0.75,IF(K36="Plab",-0.5,0))),0),IF(M37<20,IF(K37="Plec",-1,IF(K37="PTL",-0.75,IF(K37="Plab",-0.5,0))),0),IF(M38<20,IF(K38="Plec",-1,IF(K38="PTL",-0.75,IF(K38="Plab",-0.5,0))),0),IF(M39<20,IF(K39="Plec",-1,IF(K39="PTL",-0.75,IF(K39="Plab",-0.5,0))),0)) -> 0 | S30: =SUM(P30:R40) -> 0 | T30: =SUM(IF(M30="M",IF(OR(K30="lec",K30="plec",K30="slec"),1,IF(OR(K30="lab",K30="plab",K30="slab",K30="tut",K30="ptut",K30="stut"),0.5,IF(OR(K30="TL",K30="pTL",K30="STL"),0.75,0))),0),IF(M31="M",IF(OR(K31="lec",K31="plec",K31="slec"),1,IF(OR(K31="lab",K31="plab",K31="slab",K31="tut",K31="ptut",K31="stut"),0.5,IF(OR(K31="TL",K31="pTL",K31="STL"),0.75,0))),0),IF(M32="M",IF(OR(K32="lec",K32="plec",K32="slec"),1,IF(OR(K32="lab",K32="plab",K32="slab",K32="tut",K32="ptut",K32="stut"),0.5,IF(OR(K32="TL",K32="pTL",K32="STL"),0.75,0))),0),IF(M33="M",IF(OR(K33="lec",K33="plec",K33="slec"),1,IF(OR(K33="lab",K33="plab",K33="slab",K33="tut",K33="ptut",K33="stut"),0.5,IF(OR(K33="TL",K33="pTL",K33="STL"),0.75,0))),0),IF(M34="M",IF(OR(K34="lec",K34="plec",K34="slec"),1,IF(OR(K34="lab",K34="plab",K34="slab",K34="tut",K34="ptut",K34="stut"),0.5,IF(OR(K34="TL",K34="pTL",K34="STL"),0.75,0))),0),IF(M35="M",IF(OR(K35="lec",K35="plec",K35="slec"),1,IF(OR(K35="lab",K35="plab",K35="slab",K35="tut",K35="ptut",K35="stut"),0.5,IF(OR(K35="TL",K35="pTL",K35="STL"),0.75,0))),0),IF(M36="M",IF(OR(K36="lec",K36="plec",K36="slec"),1,IF(OR(K36="lab",K36="plab",K36="slab",K36="tut",K36="ptut",K36="stut"),0.5,IF(OR(K36="TL",K36="pTL",K36="STL"),0.75,0))),0),IF(M37="M",IF(OR(K37="lec",K37="plec",K37="slec"),1,IF(OR(K37="lab",K37="plab",K37="slab",K37="tut",K37="ptut",K37="stut"),0.5,IF(OR(K37="TL",K37="pTL",K37="STL"),0.75,0))),0),IF(M38="M",IF(OR(K38="lec",K38="plec",K38="slec"),1,IF(OR(K38="lab",K38="plab",K38="slab",K38="tut",K38="ptut",K38="stut"),0.5,IF(OR(K38="TL",K38="pTL",K38="STL"),0.75,0))),0),IF(M39="M",IF(OR(K39="lec",K39="plec",K39="slec"),1,IF(OR(K39="lab",K39="plab",K39="slab",K39="tut",K39="ptut",K39="stut"),0.5,IF(OR(K39="TL",K39="pTL",K39="STL"),0.75,0))),0),IF(M40="M",IF(OR(K40="lec",K40="plec",K40="slec"),1,IF(OR(K40="lab",K40="plab",K40="slab",K40="tut",K40="ptut",K40="stut"),0.5,IF(OR(K40="TL",K40="pTL",K40="STL"),0.75,0))),0)) -> 0 | X30: =S30-(T30+U30+V30+W30) -> 0 | Y30: =CONCATENATE(SUM(O30:O40),"(",SUM(O30:O40)-X30,")") -> 0(0) | AP30: =SUM(SUM(O30:O40),SUM(AI30:AI40)/2,AM30) -> 0 | AR30: =AP30*AQ30 -> 0 | AS30: =CT30 -> 5.6 | AT30: =AR30*0.75+AS30*0.25 -> 1.4 | BM30: 5.3 | BQ30: Phone call to parent for failed students in T1-PS Exam | BR30: 6 | BS30: 0 | CF30: DONE PAPER EVALUATION OF PS T-1 EXAM IN SY-2 DEPARTMENT 83 PAPERS | CS30: =SUM(IF(AU30<0,ABS(AU30),0),IF(AZ30<0,ABS(AZ30),0),ABS(CI30),ABS(CK30),ABS(CM30),ABS(CO30),ABS(CQ30),ABS(CR30)) -> 0 | CT30: =SUM(AU30,AV30,AW30,AX30/400,AY30,AZ30,BG30,BH30*0.5,BI30*0.25,BJ30,BK30,BL30,BM30,BN30,BO30,BP30,BR30/20,BS30/100,BT30/60,BU30,BV30,BW30,BX30/4,SUM(BY30:CC40)/3,CE30,CG30/3,CI30,CK30,CM30,CO30,CQ30,CR30) -> 5.6 | CU30: =D30 -> MPH
C31: 2 | D31: MPH | O31: =IF(AND(M31<>0,M31<>"m",M31<>"",RIGHT(K31,3)="Lec"),1,IF(AND(M31<>0,M31<>"m",M31<>"",OR(RIGHT(K31,3)="Lab",RIGHT(K31,3)="Tut")),0.5,IF(AND(M31<>0,M31<>"m",M31<>"",RIGHT(K31,2)="TL"),0.75,0))) -> 0 | CU31: =D31 -> MPH
C32: 3 | D32: MPH | O32: =IF(AND(M32<>0,M32<>"m",M32<>"",RIGHT(K32,3)="Lec"),1,IF(AND(M32<>0,M32<>"m",M32<>"",OR(RIGHT(K32,3)="Lab",RIGHT(K32,3)="Tut")),0.5,IF(AND(M32<>0,M32<>"m",M32<>"",RIGHT(K32,2)="TL"),0.75,0))) -> 0 | CU32: =D32 -> MPH
C33: 4 | D33: MPH | O33: =IF(AND(M33<>0,M33<>"m",M33<>"",RIGHT(K33,3)="Lec"),1,IF(AND(M33<>0,M33<>"m",M33<>"",OR(RIGHT(K33,3)="Lab",RIGHT(K33,3)="Tut")),0.5,IF(AND(M33<>0,M33<>"m",M33<>"",RIGHT(K33,2)="TL"),0.75,0))) -> 0 | CU33: =D33 -> MPH
C34: 5 | D34: MPH | O34: =IF(AND(M34<>0,M34<>"m",M34<>"",RIGHT(K34,3)="Lec"),1,IF(AND(M34<>0,M34<>"m",M34<>"",OR(RIGHT(K34,3)="Lab",RIGHT(K34,3)="Tut")),0.5,IF(AND(M34<>0,M34<>"m",M34<>"",RIGHT(K34,2)="TL"),0.75,0))) -> 0 | CU34: =D34 -> MPH
C35: 6 | D35: MPH | O35: =IF(AND(M35<>0,M35<>"m",M35<>"",RIGHT(K35,3)="Lec"),1,IF(AND(M35<>0,M35<>"m",M35<>"",OR(RIGHT(K35,3)="Lab",RIGHT(K35,3)="Tut")),0.5,IF(AND(M35<>0,M35<>"m",M35<>"",RIGHT(K35,2)="TL"),0.75,0))) -> 0 | CU35: =D35 -> MPH
C36: 7 | D36: MPH | O36: =IF(AND(M36>=20,M36<>"m",RIGHT(K36,3)="Lec"),1,IF(AND(M36>=20,M36<>"m",OR(RIGHT(K36,3)="Lab",RIGHT(K36,3)="Tut")),0.5,IF(AND(M36>=20,M36<>"m",RIGHT(K36,2)="TL"),0.75,0))) -> 0 | CU36: =D36 -> MPH
C37: 8 | D37: MPH | O37: =IF(AND(M37>=20,M37<>"m",RIGHT(K37,3)="Lec"),1,IF(AND(M37>=20,M37<>"m",OR(RIGHT(K37,3)="Lab",RIGHT(K37,3)="Tut")),0.5,IF(AND(M37>=20,M37<>"m",RIGHT(K37,2)="TL"),0.75,0))) -> 0 | CU37: =D37 -> MPH
C38: 9 | D38: MPH | O38: =IF(AND(M38>=20,M38<>"m",RIGHT(K38,3)="Lec"),1,IF(AND(M38>=20,M38<>"m",OR(RIGHT(K38,3)="Lab",RIGHT(K38,3)="Tut")),0.5,IF(AND(M38>=20,M38<>"m",RIGHT(K38,2)="TL"),0.75,0))) -> 0 | CU38: =D38 -> MPH
C39: 10 | D39: MPH | O39: =IF(AND(M39>=20,M39<>"m",RIGHT(K39,3)="Lec"),1,IF(AND(M39>=20,M39<>"m",OR(RIGHT(K39,3)="Lab",RIGHT(K39,3)="Tut")),0.5,IF(AND(M39>=20,M39<>"m",RIGHT(K39,2)="TL"),0.75,0))) -> 0 | CU39: =D39 -> MPH
C40: 11 | D40: MPH | O40: =IF(AND(M40<>0,M40<>"m",M40<>"",RIGHT(K40,3)="Lec"),1,IF(AND(M40<>0,M40<>"m",M40<>"",OR(RIGHT(K40,3)="Lab",RIGHT(K40,3)="Tut")),0.5,IF(AND(M40<>0,M40<>"m",M40<>"",RIGHT(K40,2)="TL"),0.75,0))) -> 0 | CU40: =D40 -> MPH
A41: 4 | B41: Mr.Mehul Kodiya DOJ: 16/06/2015 MOB: 9998650442 | C41: 1 | D41: MVK | O41: =IF(AND(M41<>0,M41<>"m",M41<>"",RIGHT(K41,3)="Lec"),1,IF(AND(M41<>0,M41<>"m",M41<>"",OR(RIGHT(K41,3)="Lab",RIGHT(K41,3)="Tut")),0.5,IF(AND(M41<>0,M41<>"m",M41<>"",RIGHT(K41,2)="TL"),0.75,0))) -> 0 | P41: =COUNTIF(K41:K51,"TL")*0.75+COUNTIF(K41:K51,"Lec")*1+COUNTIF(K41:K51,"Lab")*0.5 -> 0 | Q41: =SUM((IF(LEFT(K41,1)="E",O41,0)),(IF(LEFT(K42,1)="E",O42,0)),(IF(LEFT(K43,1)="E",O43,0)),(IF(LEFT(K44,1)="E",O44,0)),(IF(LEFT(K45,1)="E",O45,0)),(IF(LEFT(K46,1)="E",O46,0)),(IF(LEFT(K47,1)="E",O47,0)),(IF(LEFT(K48,1)="E",O48,0)),(IF(LEFT(K49,1)="E",O49,0)),(IF(LEFT(K50,1)="E",O50,0)),(IF(LEFT(K51,1)="E",O51,0))) -> 0 | R41: =SUM(IF(M47<20,IF(K47="Plec",-1,IF(K47="PTL",-0.75,IF(K47="Plab",-0.5,0))),0),IF(M48<20,IF(K48="Plec",-1,IF(K48="PTL",-0.75,IF(K48="Plab",-0.5,0))),0),IF(M49<20,IF(K49="Plec",-1,IF(K49="PTL",-0.75,IF(K49="Plab",-0.5,0))),0),IF(M50<20,IF(K50="Plec",-1,IF(K50="PTL",-0.75,IF(K50="Plab",-0.5,0))),0)) -> 0 | S41: =SUM(P41:R51) -> 0 | T41: =SUM(IF(M41="M",IF(OR(K41="lec",K41="plec",K41="slec"),1,IF(OR(K41="lab",K41="plab",K41="slab",K41="tut",K41="ptut",K41="stut"),0.5,IF(OR(K41="TL",K41="pTL",K41="STL"),0.75,0))),0),IF(M42="M",IF(OR(K42="lec",K42="plec",K42="slec"),1,IF(OR(K42="lab",K42="plab",K42="slab",K42="tut",K42="ptut",K42="stut"),0.5,IF(OR(K42="TL",K42="pTL",K42="STL"),0.75,0))),0),IF(M43="M",IF(OR(K43="lec",K43="plec",K43="slec"),1,IF(OR(K43="lab",K43="plab",K43="slab",K43="tut",K43="ptut",K43="stut"),0.5,IF(OR(K43="TL",K43="pTL",K43="STL"),0.75,0))),0),IF(M44="M",IF(OR(K44="lec",K44="plec",K44="slec"),1,IF(OR(K44="lab",K44="plab",K44="slab",K44="tut",K44="ptut",K44="stut"),0.5,IF(OR(K44="TL",K44="pTL",K44="STL"),0.75,0))),0),IF(M45="M",IF(OR(K45="lec",K45="plec",K45="slec"),1,IF(OR(K45="lab",K45="plab",K45="slab",K45="tut",K45="ptut",K45="stut"),0.5,IF(OR(K45="TL",K45="pTL",K45="STL"),0.75,0))),0),IF(M46="M",IF(OR(K46="lec",K46="plec",K46="slec"),1,IF(OR(K46="lab",K46="plab",K46="slab",K46="tut",K46="ptut",K46="stut"),0.5,IF(OR(K46="TL",K46="pTL",K46="STL"),0.75,0))),0),IF(M47="M",IF(OR(K47="lec",K47="plec",K47="slec"),1,IF(OR(K47="lab",K47="plab",K47="slab",K47="tut",K47="ptut",K47="stut"),0.5,IF(OR(K47="TL",K47="pTL",K47="STL"),0.75,0))),0),IF(M48="M",IF(OR(K48="lec",K48="plec",K48="slec"),1,IF(OR(K48="lab",K48="plab",K48="slab",K48="tut",K48="ptut",K48="stut"),0.5,IF(OR(K48="TL",K48="pTL",K48="STL"),0.75,0))),0),IF(M49="M",IF(OR(K49="lec",K49="plec",K49="slec"),1,IF(OR(K49="lab",K49="plab",K49="slab",K49="tut",K49="ptut",K49="stut"),0.5,IF(OR(K49="TL",K49="pTL",K49="STL"),0.75,0))),0),IF(M50="M",IF(OR(K50="lec",K50="plec",K50="slec"),1,IF(OR(K50="lab",K50="plab",K50="slab",K50="tut",K50="ptut",K50="stut"),0.5,IF(OR(K50="TL",K50="pTL",K50="STL"),0.75,0))),0),IF(M51="M",IF(OR(K51="lec",K51="plec",K51="slec"),1,IF(OR(K51="lab",K51="plab",K51="slab",K51="tut",K51="ptut",K51="stut"),0.5,IF(OR(K51="TL",K51="pTL",K51="STL"),0.75,0))),0)) -> 0 | X41: =S41-(T41+U41+V41+W41) -> 0 | Y41: =CONCATENATE(SUM(O41:O51),"(",SUM(O41:O51)-X41,")") -> 0(0) | AP41: =SUM(SUM(O41:O51),SUM(AI41:AI51)/2,AM41) -> 0 | AR41: =AP41*AQ41 -> 0 | AS41: =CT41 -> 0.2 | AT41: =AR41*0.75+AS41*0.25 -> 0.05 | BQ41: Phone call to parent for failed students in T1-PS Exam | BR41: 4 | BS41: 0 | CH41: 1 | CI41: 0 | CS41: =SUM(IF(AU41<0,ABS(AU41),0),IF(AZ41<0,ABS(AZ41),0),ABS(CI41),ABS(CK41),ABS(CM41),ABS(CO41),ABS(CQ41),ABS(CR41)) -> 0 | CT41: =SUM(AU41,AV41,AW41,AX41/400,AY41,AZ41,BG41,BH41*0.5,BI41*0.25,BJ41,BK41,BL41,BM41,BN41,BO41,BP41,BR41/20,BS41/100,BT41/60,BU41,BV41,BW41,BX41/4,SUM(BY41:CC51)/3,CE41,CG41/3,CI41,CK41,CM41,CO41,CQ41,CR41) -> 0.2 | CU41: =D41 -> MVK
...

Sheet 23 Oct Wed
A1: =CONCATENATE("DAILY REPORT DATE : ",MID(CELL("filename",A1),FIND("]",CELL("filename",A1),1)+1,255)) -> #VALUE! | AU1: =A1 -> #VALUE!
A3: COLLEGE NAME : L.J. INSTITUTE OF ENGINEERING AND TECHNOLOGY DEPARTMENT NAME : SY4(CST CS&IT) YEAR : 2024-25 SEMESTER : III | AU3: =A3 -> COLLEGE NAME : L.J. INSTITUTE OF ENGINEERING AND TECHNOLOGY DEPARTMENT NAME : SY4(CST CS&IT) YEAR : 2024-25 SEMESTER : III
A4: TEACHING SECTION | AU4: NON TEACHING SECTION | CH4: HOD SECTION
A5: LECTURE DETAILS | AA5: Difficulty solving or if attendance is less than 5 /Whatsapp Doubt Solving in official group / Students details whose Home Visit was done / PTM (Roll No,Name, Contact No.) (H) | AJ5: Project / Dissertation/Design Engineering Load (Enter only if Answer is given by Guide of the technical query) | AP5: Total Teaching Credits (A) | AQ5: Teaching Feedback (B) | AR5: Effective Teaching Credit C= A * B | AS5: NT Total Credits (D) Refer from NT Section | AT5: Final Teaching + Non Teaching Credit E =C*0.75+D*0.25 | AU5: Once in a Semester | AY5: Load Adjustment Done | AZ5: AttendanceSubmission.If Not submitted | BA5: Examination | BP5: PARENTS INTERACTION | BV5: SIF Credit | BX5: Extra Activity
A6: Sr No | B6: Name-DOJ-Mobile No. | C6: Lec. No | D6: Faculty Initials | E6: Lecture Details | M6: No. of Students Present | N6: Total Students | O6: Effective Load | P6: Today's Eff.Load Alloted as per TT | Q6: Extra Load | R6: Merged Load (If student in proxy batch < 20, mention (-1) for 2 hrs Lab or (-1.5) for 2 hrs TL | S6: Overall Today's Effective Load | T6: Today's Eff. Mass bunk | U6: Today's Eff.load cancel bcz of Holiday | V6: Today's Eff load cancel bcz of Specific reason | W6: Today's Eff load cancel bcz no adjustment was possible | X6: Today's Total Eff Load Expected from Faculty | Y6: Today's Eff.Load Taken | Z6: Comment for dummy column name C,D,E (Holiday, or load cacnelled details) | AU6: Submission of Subject Folder (LP, QB,MSE Syllabus, Ques Paper etc) Enter Credit=0 if done on time, Else (-1) daily until submitted | AV6: Timetable Preparation Credit as per GI | AW6: No.of Project/Dissertation Groups handled (To be entered at the end of semester) | AX6: No.of Marks Entry in GTU Portal | BA6: Supervision during College Exam | BJ6: Paper Setting | BK6: Paper Solution | BL6: Paper Evaluation | BO6: Paper Showing | BP6: Home Visit Credit & Enter details in (H-Teaching Section) (Credit =1 - Meeting with Mother Credit = 1.5 - Meeting with Father) | BQ6: No. of Phone Calls and entered in SIF | BT6: No. of SMS done | BU6: Personal Discussion with parents in Institute (0.25 credit per student) | BV6: Enter Credit for Personal Information in Page 1 and Page 2 | BW6: Enter credit for any entry work done in SIF | BX6: Extra Activity in hours as per General Instructions. | CF6: Not Defined as per General Instruction (Enter in terms of Hrs) | CH6: Leave Status | CJ6: Error in Work done | CL6: Delay in Work Done | CN6: Any other HOD Comment | CP6: Description of Work refused by faculty or done after doing arguments with HOD | CQ6: Enter credit if Faculty Refusd to do work given by HOD. Credit = (-5) | CR6: Enter credit if Faculty does work after doing arguments with HOD. Credit = (-2) | CS6: HOD Positive Credit and Faculty Negative Credit | CT6: Total NT Credits
